[2025-07-25 20:55:55,949: ERROR/SpawnPoolWorker-40] Pool process <billiard.pool.Worker object at 0x00000269264F0BC0> error: PermissionError(13, 'Access is denied', None, 5, None)
Traceback (most recent call last):
  File "C:\w\JoSI\data_sync_platform\.venv\Lib\site-packages\billiard\pool.py", line 473, in receive
    ready, req = _receive(1.0)
                 ^^^^^^^^^^^^^
  File "C:\w\JoSI\data_sync_platform\.venv\Lib\site-packages\billiard\pool.py", line 445, in _recv
    return True, loads(get_payload())
                       ^^^^^^^^^^^^^
  File "C:\w\JoSI\data_sync_platform\.venv\Lib\site-packages\billiard\queues.py", line 394, in get_payload
    with self._rlock:
         ^^^^^^^^^^^
  File "C:\w\JoSI\data_sync_platform\.venv\Lib\site-packages\billiard\synchronize.py", line 118, in __exit__
    return self._semlock.__exit__(*args)
           ^^^^^^^^^^^^^^^^^^^^^^^^^^^^^
OSError: [WinError 6] The handle is invalid

During handling of the above exception, another exception occurred:

Traceback (most recent call last):
  File "C:\w\JoSI\data_sync_platform\.venv\Lib\site-packages\billiard\pool.py", line 351, in workloop
    req = wait_for_job()
          ^^^^^^^^^^^^^^
  File "C:\w\JoSI\data_sync_platform\.venv\Lib\site-packages\billiard\pool.py", line 480, in receive
    raise SystemExit(EX_FAILURE)
SystemExit: 1

During handling of the above exception, another exception occurred:

Traceback (most recent call last):
  File "C:\w\JoSI\data_sync_platform\.venv\Lib\site-packages\billiard\pool.py", line 292, in __call__
    sys.exit(self.workloop(pid=pid))
             ^^^^^^^^^^^^^^^^^^^^^^
  File "C:\w\JoSI\data_sync_platform\.venv\Lib\site-packages\billiard\pool.py", line 396, in workloop
    self._ensure_messages_consumed(completed=completed)
  File "C:\w\JoSI\data_sync_platform\.venv\Lib\site-packages\billiard\pool.py", line 406, in _ensure_messages_consumed
    if self.on_ready_counter.value >= completed:
       ^^^^^^^^^^^^^^^^^^^^^^^^^^^
  File "<string>", line 3, in getvalue
PermissionError: [WinError 5] Access is denied
[2025-07-25 20:55:55,949: ERROR/SpawnPoolWorker-40] Pool process <billiard.pool.Worker object at 0x00000269264F0BC0> error: PermissionError(13, 'Access is denied', None, 5, None)
Traceback (most recent call last):
  File "C:\w\JoSI\data_sync_platform\.venv\Lib\site-packages\billiard\pool.py", line 473, in receive
    ready, req = _receive(1.0)
                 ^^^^^^^^^^^^^
  File "C:\w\JoSI\data_sync_platform\.venv\Lib\site-packages\billiard\pool.py", line 445, in _recv
    return True, loads(get_payload())
                       ^^^^^^^^^^^^^
  File "C:\w\JoSI\data_sync_platform\.venv\Lib\site-packages\billiard\queues.py", line 394, in get_payload
    with self._rlock:
         ^^^^^^^^^^^
  File "C:\w\JoSI\data_sync_platform\.venv\Lib\site-packages\billiard\synchronize.py", line 118, in __exit__
    return self._semlock.__exit__(*args)
           ^^^^^^^^^^^^^^^^^^^^^^^^^^^^^
OSError: [WinError 6] The handle is invalid

During handling of the above exception, another exception occurred:

Traceback (most recent call last):
  File "C:\w\JoSI\data_sync_platform\.venv\Lib\site-packages\billiard\pool.py", line 351, in workloop
    req = wait_for_job()
          ^^^^^^^^^^^^^^
  File "C:\w\JoSI\data_sync_platform\.venv\Lib\site-packages\billiard\pool.py", line 480, in receive
    raise SystemExit(EX_FAILURE)
SystemExit: 1

During handling of the above exception, another exception occurred:

Traceback (most recent call last):
  File "C:\w\JoSI\data_sync_platform\.venv\Lib\site-packages\billiard\pool.py", line 292, in __call__
    sys.exit(self.workloop(pid=pid))
             ^^^^^^^^^^^^^^^^^^^^^^
  File "C:\w\JoSI\data_sync_platform\.venv\Lib\site-packages\billiard\pool.py", line 396, in workloop
    self._ensure_messages_consumed(completed=completed)
  File "C:\w\JoSI\data_sync_platform\.venv\Lib\site-packages\billiard\pool.py", line 406, in _ensure_messages_consumed
    if self.on_ready_counter.value >= completed:
       ^^^^^^^^^^^^^^^^^^^^^^^^^^^
  File "<string>", line 3, in getvalue
PermissionError: [WinError 5] Access is denied
[2025-07-25 20:55:56,727: ERROR/MainProcess] Process 'SpawnPoolWorker-40' pid:38988 exited with 'exitcode 1'
